<?xml version="1.0" ?>
<sdf version="1.5">
  
  <model name="turtlebot3_burger">
  
    <plugin name="buoyancy" filename="libBuoyancyPlugin.so">
      <fluid_density>43665</fluid_density>
      <!--<fluid_density>50708.55</fluid_density>-->
    </plugin>
    <!--<fluid_density>42740</fluid_density>-->
    <!--<fluid_density>11785</fluid_density>-->

    <link name="base_link">

      <inertial>
        <pose>0 0 -0.05 0 0 0</pose>
        <inertia>
          <ixx>7.2397393e-01</ixx>
          <ixy>4.686399e-10</ixy>
          <ixz>-1.09525703e-08</ixz>
          <iyy>7.2397393e-01</iyy>
          <iyz>2.8582649e-09</iyz>
          <izz>6.53050163e-01</izz>
        </inertia>
        <mass>8.2573504e-01</mass>
      </inertial>

      <collision name="base_collision">
        <pose>0 0 -0.05 0 0 0</pose>
        <!--<pose>-0.032 0 0.070 0 0 0</pose>-->
        <geometry>
          <!--<box>
            <size>0.140 0.140 0.140</size>
          </box>-->
          <box>
            <size>0.2 0.2 0.1</size>
          </box>
        </geometry>
      </collision>

      <visual name="base_visual">
        <!--<pose>-0.032 0 0 0 0 0</pose>-->
        <pose>0 0 -0.05 0 0 0</pose>
        <geometry>
          
          <!--<mesh>
            <uri>model://turtlebot3_burger/meshes/burger_base.dae</uri>
            <scale>0.001 0.001 0.001</scale>
          </mesh>-->
          <box>
            <size>0.2 0.2 0.1</size>
          </box>
        </geometry>
      </visual>
    </link>

    

    <!--<link name="imu_link">
      <sensor name="tb3_imu" type="imu">
        <always_on>true</always_on>
        <update_rate>200</update_rate>
        <imu>
          <angular_velocity>
            <x>
              <noise type="gaussian">
                <mean>0.0</mean>
                <stddev>2e-4</stddev>
              </noise>
            </x>
            <y>
              <noise type="gaussian">
                <mean>0.0</mean>
                <stddev>2e-4</stddev>
              </noise>
            </y>
            <z>
              <noise type="gaussian">
                <mean>0.0</mean>
                <stddev>2e-4</stddev>
              </noise>
            </z>
          </angular_velocity>
          <linear_acceleration>
            <x>
              <noise type="gaussian">
                <mean>0.0</mean>
                <stddev>1.7e-2</stddev>
              </noise>
            </x>
            <y>
              <noise type="gaussian">
                <mean>0.0</mean>
                <stddev>1.7e-2</stddev>
              </noise>
            </y>
            <z>
              <noise type="gaussian">
                <mean>0.0</mean>
                <stddev>1.7e-2</stddev>
              </noise>
            </z>
          </linear_acceleration>
        </imu>
        <plugin name="turtlebot3_imu" filename="libgazebo_ros_imu_sensor.so">
          <ros>
            <remapping>~/out:=imu</remapping>
          </ros>
        </plugin>
      </sensor>
    </link>-->

    <link name="base_scan">
      <inertial>
        <pose>0 0 0.02 0 0 0</pose>
        <inertia>
          <ixx>0.001</ixx>
          <ixy>0.000</ixy>
          <ixz>0.000</ixz>
          <iyy>0.001</iyy>
          <iyz>0.000</iyz>
          <izz>0.001</izz>
        </inertia>
        <mass>0.114</mass>
      </inertial>


    <!--add-->
      <collision name="lidar_sensor_collision">
        <pose>0 0 0.02 0 0 0</pose>
        <geometry>
          <!--<cylinder>
            <radius>0.0508</radius>
            <length>0.055</length>
          </cylinder>-->
          <box>
            <size>0.000001 0.000001 0.000001</size>
          </box>
        </geometry>
      </collision>

      <visual name="lidar_sensor_visual">
        <pose>0 0 0.03 0 0 0</pose>
        <geometry>
           <mesh>
            <uri>model://turtlebot3_burger/meshes/lds.dae</uri>
            <scale>0.001 0.001 0.001</scale>
          </mesh>
          <!--<box>
            <size>0.1 0.1 0.1</size>
          </box>-->
        </geometry>
      </visual>

      <sensor name="hls_lfcd_lds" type="ray">
        <pose>0.0 0 0.03 0 0 0</pose>
        <visualize>true</visualize>
        <update_rate>1</update_rate>
        <ray>
          <scan>
            <!--<horizontal>
              <samples>36</samples>
              <resolution>1</resolution> 
              <min_angle>0.000000</min_angle>
              <max_angle>6.280000</max_angle>
            </horizontal>
            <vertical>
              <samples>9</samples>
              <resolution>1</resolution> 
              <min_angle>-0.2</min_angle>
              <max_angle>1</max_angle> 
            </vertical>-->
          </scan>
          <range>
            <min>0.12</min>
            <max>1.5</max>
            <resolution>0.02</resolution>
          </range>
        </ray>
        <plugin name="turtlebot3_laserscan" filename="libgazebo_ros_ray_sensor.so">
          <ros>
            <remapping>~/out:=scanup</remapping>
          </ros>
          <output_type>sensor_msgs/LaserScan</output_type>
          <frame_name>base_scan</frame_name>
        </plugin>
        
      </sensor>
    <!--addend-->
    </link>





    <!--add-->
    

    
    <!--addend-->

    <!--<joint name="base_joint" type="fixed">
      <parent>base_footprint</parent>
      <child>base_link</child>
      <pose>0.0 0.0 0.010 0 0 0</pose>
    </joint>-->

    

    <!--<joint name="imu_joint" type="fixed">
      <parent>base_link</parent>
      <child>imu_link</child>
      <pose>-0.032 0 0.068 0 0 0</pose>
      <axis>
        <xyz>0 0 1</xyz>
      </axis>
    </joint>-->



    <!--add-->

    <!--<joint name="sonar_front_joint" type="fixed">
      <axis>
        <xyz>0 1 0</xyz>
      </axis>
      <origin> 
        <rpy>0 0 0</rpy>
        <xyz>0.03 0 0.15</xyz>
      </origin>
      <parent>base_link</parent>
      <child>base_scan</child>
    </joint>-->

    <joint name="lidar_joint" type="fixed">
      <parent>base_link</parent>
      <child>base_scan</child>
      <pose>0.0 0 0.03 0 0 0</pose>
      <axis>
        <xyz>0 0 1</xyz>
      </axis>
    </joint>


    <link name="base_scan2">
      <inertial>
        <pose>0 0 -0.13 0 0 0</pose>
        <inertia>
          <ixx>0.001</ixx>
          <ixy>0.000</ixy>
          <ixz>0.000</ixz>
          <iyy>0.001</iyy>
          <iyz>0.000</iyz>
          <izz>0.001</izz>
        </inertia>
        <mass>0.114</mass>
      </inertial>


    <!--add-->
      <collision name="lidar_sensor_collision">
        <pose>0 0 -0.12 0 0 0</pose>
        <geometry>
          <!--<cylinder>
            <radius>0.0508</radius>
            <length>0.055</length>
          </cylinder>-->
          <box>
            <size>0.000001 0.000001 0.000001</size>
          </box>
        </geometry>
      </collision>

      <visual name="lidar_sensor_visual">
        <pose>0 0 -0.13 3.14159265 0 0</pose>
        <geometry>
           <mesh>
            <uri>model://turtlebot3_burger/meshes/lds.dae</uri>
            <scale>0.001 0.001 0.001</scale>
          </mesh>
          <!--<box>
            <size>0.1 0.1 0.1</size>
          </box>-->
        </geometry>
      </visual>

      <sensor name="hls_lfcd_lds" type="ray">
        <pose>0.0 0 -0.13 0 0 0</pose>
        <visualize>true</visualize>
        <update_rate>1</update_rate>
        <ray>
          <scan>
            <!--<horizontal>
              <samples>36</samples>
              <resolution>1</resolution> 
              <min_angle>0.000000</min_angle>
              <max_angle>6.280000</max_angle>
            </horizontal>
            <vertical>
              <samples>9</samples>
              <resolution>1</resolution> 
              <min_angle>-1</min_angle>
              <max_angle>0.2</max_angle> 
            </vertical>-->
          </scan>
          <range>
            <min>0.12</min>
            <max>1.5</max>
            <resolution>0.02</resolution>
          </range>
        </ray>
        <plugin name="turtlebot3_laserscan" filename="libgazebo_ros_ray_sensor.so">
          <ros>
            <remapping>~/out:=scandown</remapping>
          </ros>
          <output_type>sensor_msgs/LaserScan</output_type>
          <frame_name>base_scan</frame_name>
        </plugin>
        
      </sensor>
    <!--addend-->
    </link>


    <joint name="lidar_joint2" type="fixed">
      <parent>base_link</parent>
      <child>base_scan2</child>
      <pose>0.0 0 -0.13 0 0 0</pose>
      <axis>
        <xyz>0 0 1</xyz>
      </axis>
    </joint>

  <!--wheel-->
    <link name="wheel_left_link">

      <inertial>
        <pose>0 0.18 -0.123 -1.57 0 0</pose>
        <inertia>
          <ixx>1.8158194e-03</ixx>
          <ixy>-9.3392e-12</ixy>
          <ixz>1.04909e-11</ixz>
          <iyy>3.2922126e-03</iyy>
          <iyz>5.75694e-11</iyz>
          <izz>1.8158194e-03</izz>
        </inertia>
        <mass>2.8498940e-02</mass>
      </inertial>

      <collision name="wheel_left_collision">
        <pose>0 0.18 -0.123 -1.57 0 0</pose>
        <geometry>
          <cylinder>
            <radius>0.033</radius>
            <length>0.018</length>
          </cylinder>
        </geometry>
        <surface>
          <friction>
            <ode>
              <mu>100000.0</mu>
              <mu2>100000.0</mu2>
              <fdir1>0 0 0</fdir1>
              <slip1>0.0</slip1>
              <slip2>0.0</slip2>
            </ode>
          </friction>
          <contact>
            <ode>
              <soft_cfm>0</soft_cfm>
              <soft_erp>0.2</soft_erp>
              <kp>1e+5</kp>
              <kd>1</kd>
              <max_vel>0.01</max_vel>
              <min_depth>0.001</min_depth>
            </ode>
          </contact>
        </surface>
      </collision>

      <visual name="wheel_left_visual">
        <pose>0 0.18 -0.123 0 0 0</pose>
        <geometry>
          <mesh>
            <uri>model://turtlebot3_burger/meshes/tire.dae</uri>
            <scale>0.001 0.001 0.001</scale>
          </mesh>
        </geometry>
      </visual>
    </link>

    <link name="wheel_right_link">

      <inertial>
        <pose>0.0 -0.18 -0.123 -1.57 0 0</pose>
        <inertia>
          <ixx>1.8158194e-03</ixx>
          <ixy>-9.3392e-12</ixy>
          <ixz>1.04909e-11</ixz>
          <iyy>3.2922126e-03</iyy>
          <iyz>5.75694e-11</iyz>
          <izz>1.8158194e-03</izz>
        </inertia>
        <mass>2.8498940e-02</mass>
      </inertial>

      <collision name="wheel_right_collision">
        <pose>0.0 -0.18 -0.123 -1.57 0 0</pose>
        <geometry>
          <cylinder>
            <radius>0.033</radius>
            <length>0.018</length>
          </cylinder>
        </geometry>
        <surface>
          <friction>
            <ode>
              <mu>100000.0</mu>
              <mu2>100000.0</mu2>
              <fdir1>0 0 0</fdir1>
              <slip1>0.0</slip1>
              <slip2>0.0</slip2>
            </ode>
          </friction>
          <contact>
            <ode>
              <soft_cfm>0</soft_cfm>
              <soft_erp>0.2</soft_erp>
              <kp>1e+5</kp>
              <kd>1</kd>
              <max_vel>0.01</max_vel>
              <min_depth>0.001</min_depth>
            </ode>
          </contact>
        </surface>
      </collision>
      <visual name="wheel_right_visual">
        <pose>0.0 -0.18 -0.123 0 0 0</pose>
        <geometry>
          <mesh>
            <uri>model://turtlebot3_burger/meshes/tire.dae</uri>
            <scale>0.001 0.001 0.001</scale>
          </mesh>
        </geometry>
      </visual>
    </link>

    <link name='caster_back_link'>
      <pose>-0.081 0 -0.004 -1.57 0 0</pose>
      <inertial>
        <mass>0.005</mass>
        <inertia>
          <ixx>0.001</ixx>
          <ixy>0.000</ixy>
          <ixz>0.000</ixz>
          <iyy>0.001</iyy>
          <iyz>0.000</iyz>
          <izz>0.001</izz>
        </inertia>
      </inertial>
      <collision name='collision'>
        <geometry>
          <sphere>
            <radius>0.005000</radius>
          </sphere>
        </geometry>
        <surface>
          <contact>
            <ode>
              <soft_cfm>0</soft_cfm>
              <soft_erp>0.2</soft_erp>
              <kp>1e+5</kp>
              <kd>1</kd>
              <max_vel>0.01</max_vel>
              <min_depth>0.001</min_depth>
            </ode>
          </contact>
        </surface>
      </collision>
      
    </link>

    <joint name="wheel_left_joint" type="revolute">
      <parent>base_link</parent>
      <child>wheel_left_link</child>
      <pose>0.0 0.08 -0.123 -1.57 0 0</pose>
      <axis>
        <xyz>0 0 1</xyz>
      </axis>
    </joint>

    <joint name="wheel_right_joint" type="revolute">
      <parent>base_link</parent>
      <child>wheel_right_link</child>
      <pose>0.0 -0.08 -0.123 -1.57 0 0</pose>
      <axis>
        <xyz>0 0 1</xyz>
      </axis>
    </joint>

    <joint name='caster_back_joint' type='ball'>
      <parent>base_link</parent>
      <child>caster_back_link</child>
    </joint>







    <plugin name="turtlebot3_diff_drive" filename="libgazebo_ros_diff_drive.so">

      <ros>
        <!-- <namespace>/tb3</namespace> -->
      </ros>

      <update_rate>30</update_rate>

      <!-- wheels -->
      <right_joint>wheel_right_joint</right_joint>
      <left_joint>wheel_left_joint</left_joint>
      
      <!-- kinematics -->
      <wheel_separation>0.160</wheel_separation>
      <wheel_diameter>0.066</wheel_diameter>

      <!-- limits -->
      <max_wheel_torque>20</max_wheel_torque>
      <max_wheel_acceleration>1.0</max_wheel_acceleration>

      <command_topic>cmd_vel</command_topic>

      <!-- output -->
      <publish_odom>true</publish_odom>
      <publish_odom_tf>true</publish_odom_tf>
      <publish_wheel_tf>false</publish_wheel_tf>

      <odometry_topic>odom</odometry_topic>
      <odometry_frame>odom</odometry_frame>
      <robot_base_frame>base_link</robot_base_frame>

    </plugin>
    <plugin name="turtlebot3_joint_state" filename="libgazebo_ros_joint_state_publisher.so">
      <ros>
        <!-- <namespace>/tb3</namespace> -->
        <remapping>~/out:=joint_states</remapping>
      </ros>
      <update_rate>30</update_rate>
      <joint_name>wheel_left_joint</joint_name>
      <joint_name>wheel_right_joint</joint_name>
    </plugin>      



    <link name='propeller1'>
      <!--<pose>0.0707106781185 0.0707106781185 -0.1 0 2.35619448 0</pose>-->
      <pose>0.1 0 -0.11 0 0 0</pose>
      <inertial>
        <mass>21.820000000000004</mass>
        <inertia>
          <ixx>0.45999415237916674</ixx>
          <ixy>0</ixy>
          <ixz>0</ixz>
          <iyy>0.45999415237916674</iyy>
          <iyz>0</iyz>
          <izz>0.9091666666666668</izz>
        </inertia>
      </inertial>

      
        <visual name=blade1_visual1>
          <pose>0.01716701 0.0 0 0.7853981633974483 0 0.0</pose>
            <geometry>
              <box>
                <size>0.025 0.01 0.0027275</size>
              </box>
            </geometry>
          <material>
            <script>
              <uri>file://media/materials/scripts/gazebo.material</uri>
              <name>Gazebo/Yellow</name>
            </script>
          </material>
        </visual>
        <collision name=blade1_collision1>
          <pose>0.01716701 0.0 0 0.7853981633974483 0 0.0</pose>
            <geometry>
              <box>
                <size>0.025 0.01 0.0027275</size>
              </box>
            </geometry>
        </collision>
        <visual name=blade2_visual1>
          <pose>0.0 0.01716701 0 0.7853981633974483 0 1.5707963267948966</pose>
            <geometry>
              <box>
                <size>0.025 0.01 0.0027275</size>
              </box>
            </geometry>
          <material>
            <script>
              <uri>file://media/materials/scripts/gazebo.material</uri>
              <name>Gazebo/Yellow</name>
            </script>
          </material>
        </visual>
        <collision name=blade2_collision1>
          <pose>0.0 0.01716701 0 0.7853981633974483 0 1.57079632679489606</pose>
            <geometry>
              <box>
                <size>0.025 0.01 0.0027275</size>
              </box>
            </geometry>
        </collision>
      
        <visual name=blade3_visual1>
          <pose>-0.01716701 -0.0 0 -0.7853981633974483 0 0.0</pose>
            <geometry>
              <box>
                <size>0.025 0.01 0.0027275</size>
              </box>
            </geometry>
          <material>
            <script>
              <uri>file://media/materials/scripts/gazebo.material</uri>
              <name>Gazebo/Yellow</name>
            </script>
          </material>
        </visual>
        <collision name=blade3_collision1>
          <pose>-0.01716701 -0.0 0 -0.7853981633974483 0 0.0</pose>
            <geometry>
              <box>
                <size>0.025 0.01 0.0027275</size>
              </box>
            </geometry>
        </collision>
      
        <visual name=blade4_visual1>
          <pose>-0.0 -0.01716701 0 -0.7853981633974483 0 1.5707963267948966</pose>
            <geometry>
              <box>
                <size>0.025 0.01 0.0027275</size>
              </box>
            </geometry>
          <material>
            <script>
              <uri>file://media/materials/scripts/gazebo.material</uri>
              <name>Gazebo/Yellow</name>
            </script>
          </material>
        </visual>
        <collision name=blade4_collision1>
          <pose>-0.0 -0.01716701 0 -0.7853981633974483 0 1.5707963267948966</pose>
            <geometry>
              <box>
                <size>0.025 0.01 0.0027275</size>
              </box>
            </geometry>
        </collision>

    </link>

    <joint name='spinning_joint1' type='revolute'>
      <parent>base_link</parent>
      <child>propeller1</child>
      <axis>
        <xyz>0 0 1</xyz>
        <!--<xyz>0.707106781185 0.707106781185 -1</xyz>-->
        <use_parent_model_frame>1</use_parent_model_frame>
        <limit>
          <lower>-1e+12</lower>
          <upper>1e+12</upper>
          <effort>-1</effort>
          <velocity>-1</velocity>
        </limit>
      </axis>
    </joint>

    <plugin name="submarine_propeller_1_1" filename="libLiftDragPlugin.so">
      <air_density>1000</air_density><cla>1.2535816618911175</cla><cla_stall>-1.4326647564469914</cla_stall><cda>0</cda><cda_stall>1.4326647564469914</cda_stall><alpha_stall>1.396</alpha_stall><a0>0</a0>
      <area>0.27637</area>
      <upward>0 -0.7071067811865476 -0.7071067811865475</upward>
      <forward>0 -0.7071067811865475 0.7071067811865476</forward>
      <link_name>propeller1</link_name>
      <cp>0.35 0 0</cp>
    </plugin>
    <plugin name="submarine_propeller_2_1" filename="libLiftDragPlugin.so">
      <air_density>1000</air_density><cla>1.2535816618911175</cla><cla_stall>-1.4326647564469914</cla_stall><cda>0</cda><cda_stall>1.4326647564469914</cda_stall><alpha_stall>1.396</alpha_stall><a0>0</a0>
      <area>0.27637</area>
      <upward>-0.7071067811865475 0 -0.7071067811865476</upward>
      <forward>-0.7071067811865476 0 0.7071067811865475</forward>
      <link_name>propeller1</link_name>
      <cp>0 -0.35 0</cp>
    </plugin>

    <plugin name="submarine_propeller_3_1" filename="libLiftDragPlugin.so">
      <air_density>1000</air_density><cla>1.2535816618911175</cla><cla_stall>-1.4326647564469914</cla_stall><cda>0</cda><cda_stall>1.4326647564469914</cda_stall><alpha_stall>1.396</alpha_stall><a0>0</a0>
      <area>0.27637</area>
      <upward>0 0.7071067811865475 -0.7071067811865476</upward>
      <forward>0 -0.7071067811865476 -0.7071067811865475</forward>
      <link_name>propeller1</link_name>
      <cp>-0.35 0 0</cp>
    </plugin>

    <plugin name="submarine_propeller_4_1" filename="libLiftDragPlugin.so">
      <air_density>1000</air_density><cla>1.2535816618911175</cla><cla_stall>-1.4326647564469914</cla_stall><cda>0</cda><cda_stall>1.4326647564469914</cda_stall><alpha_stall>1.396</alpha_stall><a0>0</a0>
      <area>0.27637</area>
      <upward>0.7071067811865476 0 -0.7071067811865475</upward>
      <forward>0.7071067811865475 0 0.7071067811865476</forward>
      <link_name>propeller1</link_name>
      <cp>0 0.35 0</cp>
    </plugin>


    <link name='propeller2'>
      <pose>-0.1 0 -0.11 0 0 0</pose>
      <inertial>
        <mass>21.820000000000004</mass>
        <inertia>
          <ixx>0.45999415237916674</ixx>
          <ixy>0</ixy>
          <ixz>0</ixz>
          <iyy>0.45999415237916674</iyy>
          <iyz>0</iyz>
          <izz>0.9091666666666668</izz>
        </inertia>
      </inertial>

      
        <visual name=blade1_visual2>
          <pose>0.01716701 0.0 0 0.7853981633974483 0 0.0</pose>
            <geometry>
              <box>
                <size>0.025 0.01 0.0027275</size>
              </box>
            </geometry>
          <material>
            <script>
              <uri>file://media/materials/scripts/gazebo.material</uri>
              <name>Gazebo/Yellow</name>
            </script>
          </material>
        </visual>
        <collision name=blade1_collision2>
          <pose>0.01716701 0.0 0 0.7853981633974483 0 0.0</pose>
            <geometry>
              <box>
                <size>0.025 0.01 0.0027275</size>
              </box>
            </geometry>
        </collision>
        <visual name=blade2_visual2>
          <pose>0.0 0.01716701 0 0.7853981633974483 0 1.5707963267948966</pose>
            <geometry>
              <box>
                <size>0.025 0.01 0.0027275</size>
              </box>
            </geometry>
          <material>
            <script>
              <uri>file://media/materials/scripts/gazebo.material</uri>
              <name>Gazebo/Yellow</name>
            </script>
          </material>
        </visual>
        <collision name=blade2_collision2>
          <pose>0.0 0.01716701 0 0.7853981633974483 0 1.57079632679489606</pose>
            <geometry>
              <box>
                <size>0.025 0.01 0.0027275</size>
              </box>
            </geometry>
        </collision>
      
        <visual name=blade3_visual2>
          <pose>-0.01716701 -0.0 0 -0.7853981633974483 0 0.0</pose>
            <geometry>
              <box>
                <size>0.025 0.01 0.0027275</size>
              </box>
            </geometry>
          <material>
            <script>
              <uri>file://media/materials/scripts/gazebo.material</uri>
              <name>Gazebo/Yellow</name>
            </script>
          </material>
        </visual>
        <collision name=blade3_collision2>
          <pose>-0.01716701 -0.0 0 -0.7853981633974483 0 0.0</pose>
            <geometry>
              <box>
                <size>0.025 0.01 0.0027275</size>
              </box>
            </geometry>
        </collision>
      
        <visual name=blade4_visual2>
          <pose>-0.0 -0.01716701 0 -0.7853981633974483 0 1.5707963267948966</pose>
            <geometry>
              <box>
                <size>0.025 0.01 0.0027275</size>
              </box>
            </geometry>
          <material>
            <script>
              <uri>file://media/materials/scripts/gazebo.material</uri>
              <name>Gazebo/Yellow</name>
            </script>
          </material>
        </visual>
        <collision name=blade4_collision2>
          <pose>-0.0 -0.01716701 0 -0.7853981633974483 0 1.5707963267948966</pose>
            <geometry>
              <box>
                <size>0.025 0.01 0.0027275</size>
              </box>
            </geometry>
        </collision>

    </link>

    <joint name='spinning_joint2' type='revolute'>
      <parent>base_link</parent>
      <child>propeller2</child>
      <axis>
        <xyz>0 0 1</xyz>
        <use_parent_model_frame>1</use_parent_model_frame>
        <limit>
          <lower>-1e+12</lower>
          <upper>1e+12</upper>
          <effort>-1</effort>
          <velocity>-1</velocity>
        </limit>
      </axis>
    </joint>

    <plugin name="submarine_propeller_1_2" filename="libLiftDragPlugin.so">
      <air_density>1000</air_density><cla>1.2535816618911175</cla><cla_stall>-1.4326647564469914</cla_stall><cda>0</cda><cda_stall>1.4326647564469914</cda_stall><alpha_stall>1.396</alpha_stall><a0>0</a0>
      <area>0.27637</area>
      <upward>0 -0.7071067811865476 -0.7071067811865475</upward>
      <forward>0 -0.7071067811865475 0.7071067811865476</forward>
      <link_name>propeller2</link_name>
      <cp>0.35 0 0</cp>
    </plugin>
    <plugin name="submarine_propeller_2_2" filename="libLiftDragPlugin.so">
      <air_density>1000</air_density><cla>1.2535816618911175</cla><cla_stall>-1.4326647564469914</cla_stall><cda>0</cda><cda_stall>1.4326647564469914</cda_stall><alpha_stall>1.396</alpha_stall><a0>0</a0>
      <area>0.27637</area>
      <upward>-0.7071067811865475 0 -0.7071067811865476</upward>
      <forward>-0.7071067811865476 0 0.7071067811865475</forward>
      <link_name>propeller2</link_name>
      <cp>0 -0.35 0</cp>
    </plugin>

    <plugin name="submarine_propeller_3_2" filename="libLiftDragPlugin.so">
      <air_density>1000</air_density><cla>1.2535816618911175</cla><cla_stall>-1.4326647564469914</cla_stall><cda>0</cda><cda_stall>1.4326647564469914</cda_stall><alpha_stall>1.396</alpha_stall><a0>0</a0>
      <area>0.27637</area>
      <upward>0 0.7071067811865475 -0.7071067811865476</upward>
      <forward>0 -0.7071067811865476 -0.7071067811865475</forward>
      <link_name>propeller2</link_name>
      <cp>-0.35 0 0</cp>
    </plugin>

    <plugin name="submarine_propeller_4_2" filename="libLiftDragPlugin.so">
      <air_density>1000</air_density><cla>1.2535816618911175</cla><cla_stall>-1.4326647564469914</cla_stall><cda>0</cda><cda_stall>1.4326647564469914</cda_stall><alpha_stall>1.396</alpha_stall><a0>0</a0>
      <area>0.27637</area>
      <upward>0.7071067811865476 0 -0.7071067811865475</upward>
      <forward>0.7071067811865475 0 0.7071067811865476</forward>
      <link_name>propeller2</link_name>
      <cp>0 0.35 0</cp>
    </plugin>


    <link name='propeller3'>
      <pose>0 0.1 -0.11 0 0 0</pose>
      <inertial>
        <mass>21.820000000000004</mass>
        <inertia>
          <ixx>0.45999415237916674</ixx>
          <ixy>0</ixy>
          <ixz>0</ixz>
          <iyy>0.45999415237916674</iyy>
          <iyz>0</iyz>
          <izz>0.9091666666666668</izz>
        </inertia>
      </inertial>

      
        <visual name=blade1_visual3>
          <pose>0.01716701 0.0 0 0.7853981633974483 0 0.0</pose>
            <geometry>
              <box>
                <size>0.025 0.01 0.0027275</size>
              </box>
            </geometry>
          <material>
            <script>
              <uri>file://media/materials/scripts/gazebo.material</uri>
              <name>Gazebo/Yellow</name>
            </script>
          </material>
        </visual>
        <collision name=blade1_collision3>
          <pose>0.01716701 0.0 0 0.7853981633974483 0 0.0</pose>
            <geometry>
              <box>
                <size>0.025 0.01 0.0027275</size>
              </box>
            </geometry>
        </collision>
        <visual name=blade2_visual3>
          <pose>0.0 0.01716701 0 0.7853981633974483 0 1.5707963267948966</pose>
            <geometry>
              <box>
                <size>0.025 0.01 0.0027275</size>
              </box>
            </geometry>
          <material>
            <script>
              <uri>file://media/materials/scripts/gazebo.material</uri>
              <name>Gazebo/Yellow</name>
            </script>
          </material>
        </visual>
        <collision name=blade2_collision3>
          <pose>0.0 0.01716701 0 0.7853981633974483 0 1.57079632679489606</pose>
            <geometry>
              <box>
                <size>0.025 0.01 0.0027275</size>
              </box>
            </geometry>
        </collision>
      
        <visual name=blade3_visual3>
          <pose>-0.01716701 -0.0 0 -0.7853981633974483 0 0.0</pose>
            <geometry>
              <box>
                <size>0.025 0.01 0.0027275</size>
              </box>
            </geometry>
          <material>
            <script>
              <uri>file://media/materials/scripts/gazebo.material</uri>
              <name>Gazebo/Yellow</name>
            </script>
          </material>
        </visual>
        <collision name=blade3_collision3>
          <pose>-0.01716701 -0.0 0 -0.7853981633974483 0 0.0</pose>
            <geometry>
              <box>
                <size>0.025 0.01 0.0027275</size>
              </box>
            </geometry>
        </collision>
      
        <visual name=blade4_visual3>
          <pose>-0.0 -0.01716701 0 -0.7853981633974483 0 1.5707963267948966</pose>
            <geometry>
              <box>
                <size>0.025 0.01 0.0027275</size>
              </box>
            </geometry>
          <material>
            <script>
              <uri>file://media/materials/scripts/gazebo.material</uri>
              <name>Gazebo/Yellow</name>
            </script>
          </material>
        </visual>
        <collision name=blade4_collision3>
          <pose>-0.0 -0.01716701 0 -0.7853981633974483 0 1.5707963267948966</pose>
            <geometry>
              <box>
                <size>0.025 0.01 0.0027275</size>
              </box>
            </geometry>
        </collision>

    </link>

    <joint name='spinning_joint3' type='revolute'>
      <parent>base_link</parent>
      <child>propeller3</child>
      <axis>
        <xyz>0 0 1</xyz>
        <use_parent_model_frame>1</use_parent_model_frame>
        <limit>
          <lower>-1e+12</lower>
          <upper>1e+12</upper>
          <effort>-1</effort>
          <velocity>-1</velocity>
        </limit>
      </axis>
    </joint>

    <plugin name="submarine_propeller_1_3" filename="libLiftDragPlugin.so">
      <air_density>1000</air_density><cla>1.2535816618911175</cla><cla_stall>-1.4326647564469914</cla_stall><cda>0</cda><cda_stall>1.4326647564469914</cda_stall><alpha_stall>1.396</alpha_stall><a0>0</a0>
      <area>0.27637</area>
      <upward>0 -0.7071067811865476 -0.7071067811865475</upward>
      <forward>0 -0.7071067811865475 0.7071067811865476</forward>
      <link_name>propeller3</link_name>
      <cp>0.35 0 0</cp>
    </plugin>
    <plugin name="submarine_propeller_2_3" filename="libLiftDragPlugin.so">
      <air_density>1000</air_density><cla>1.2535816618911175</cla><cla_stall>-1.4326647564469914</cla_stall><cda>0</cda><cda_stall>1.4326647564469914</cda_stall><alpha_stall>1.396</alpha_stall><a0>0</a0>
      <area>0.27637</area>
      <upward>-0.7071067811865475 0 -0.7071067811865476</upward>
      <forward>-0.7071067811865476 0 0.7071067811865475</forward>
      <link_name>propeller3</link_name>
      <cp>0 -0.35 0</cp>
    </plugin>

    <plugin name="submarine_propeller_3_3" filename="libLiftDragPlugin.so">
      <air_density>1000</air_density><cla>1.2535816618911175</cla><cla_stall>-1.4326647564469914</cla_stall><cda>0</cda><cda_stall>1.4326647564469914</cda_stall><alpha_stall>1.396</alpha_stall><a0>0</a0>
      <area>0.27637</area>
      <upward>0 0.7071067811865475 -0.7071067811865476</upward>
      <forward>0 -0.7071067811865476 -0.7071067811865475</forward>
      <link_name>propeller3</link_name>
      <cp>-0.35 0 0</cp>
    </plugin>

    <plugin name="submarine_propeller_4_3" filename="libLiftDragPlugin.so">
      <air_density>1000</air_density><cla>1.2535816618911175</cla><cla_stall>-1.4326647564469914</cla_stall><cda>0</cda><cda_stall>1.4326647564469914</cda_stall><alpha_stall>1.396</alpha_stall><a0>0</a0>
      <area>0.27637</area>
      <upward>0.7071067811865476 0 -0.7071067811865475</upward>
      <forward>0.7071067811865475 0 0.7071067811865476</forward>
      <link_name>propeller3</link_name>
      <cp>0 0.35 0</cp>
    </plugin>


    <link name='propeller4'>
      <pose>0 -0.1 -0.11 0 0 0</pose>
      <inertial>
        <mass>21.820000000000004</mass>
        <inertia>
          <ixx>0.45999415237916674</ixx>
          <ixy>0</ixy>
          <ixz>0</ixz>
          <iyy>0.45999415237916674</iyy>
          <iyz>0</iyz>
          <izz>0.9091666666666668</izz>
        </inertia>
      </inertial>

      
        <visual name=blade1_visual4>
          <pose>0.01716701 0.0 0 0.7853981633974483 0 0.0</pose>
            <geometry>
              <box>
                <size>0.025 0.01 0.0027275</size>
              </box>
            </geometry>
          <material>
            <script>
              <uri>file://media/materials/scripts/gazebo.material</uri>
              <name>Gazebo/Yellow</name>
            </script>
          </material>
        </visual>
        <collision name=blade1_collision4>
          <pose>0.01716701 0.0 0 0.7853981633974483 0 0.0</pose>
            <geometry>
              <box>
                <size>0.025 0.01 0.0027275</size>
              </box>
            </geometry>
        </collision>
        <visual name=blade2_visual4>
          <pose>0.0 0.01716701 0 0.7853981633974483 0 1.5707963267948966</pose>
            <geometry>
              <box>
                <size>0.025 0.01 0.00272775</size>
              </box>
            </geometry>
          <material>
            <script>
              <uri>file://media/materials/scripts/gazebo.material</uri>
              <name>Gazebo/Yellow</name>
            </script>
          </material>
        </visual>
        <collision name=blade2_collision4>
          <pose>0.0 0.01716701 0 0.7853981633974483 0 1.57079632679489606</pose>
            <geometry>
              <box>
                <size>0.025 0.01 0.00272775</size>
              </box>
            </geometry>
        </collision>
      
        <visual name=blade3_visual4>
          <pose>-0.01716701 -0.0 0 -0.7853981633974483 0 0.0</pose>
            <geometry>
              <box>
                <size>0.025 0.01 0.0027275</size>
              </box>
            </geometry>
          <material>
            <script>
              <uri>file://media/materials/scripts/gazebo.material</uri>
              <name>Gazebo/Yellow</name>
            </script>
          </material>
        </visual>
        <collision name=blade3_collision4>
          <pose>-0.01716701 -0.0 0 -0.7853981633974483 0 0.0</pose>
            <geometry>
              <box>
                <size>0.025 0.01 0.0027275</size>
              </box>
            </geometry>
        </collision>
      
        <visual name=blade4_visual4>
          <pose>-0.0 -0.01716701 0 -0.7853981633974483 0 1.5707963267948966</pose>
            <geometry>
              <box>
                <size>0.025 0.01 0.0027275</size>
              </box>
            </geometry>
          <material>
            <script>
              <uri>file://media/materials/scripts/gazebo.material</uri>
              <name>Gazebo/Yellow</name>
            </script>
          </material>
        </visual>
        <collision name=blade4_collision4>
          <pose>-0.0 -0.01716701 0 -0.7853981633974483 0 1.5707963267948966</pose>
            <geometry>
              <box>
                <size>0.025 0.01 0.0027275</size>
              </box>
            </geometry>
        </collision>

    </link>

    <joint name='spinning_joint4' type='revolute'>
      <parent>base_link</parent>
      <child>propeller4</child>
      <axis>
        <xyz>0 0 1</xyz>
        <use_parent_model_frame>1</use_parent_model_frame>
        <limit>
          <lower>-1e+12</lower>
          <upper>1e+12</upper>
          <effort>-1</effort>
          <velocity>-1</velocity>
        </limit>
      </axis>
    </joint>

    <plugin name="submarine_propeller_1_4" filename="libLiftDragPlugin.so">
      <air_density>1000</air_density><cla>1.2535816618911175</cla><cla_stall>-1.4326647564469914</cla_stall><cda>0</cda><cda_stall>1.4326647564469914</cda_stall><alpha_stall>1.396</alpha_stall><a0>0</a0>
      <area>0.27637</area>
      <upward>0 -0.7071067811865476 -0.7071067811865475</upward>
      <forward>0 -0.7071067811865475 0.7071067811865476</forward>
      <link_name>propeller4</link_name>
      <cp>0.35 0 0</cp>
    </plugin>
    <plugin name="submarine_propeller_2_4" filename="libLiftDragPlugin.so">
      <air_density>1000</air_density><cla>1.2535816618911175</cla><cla_stall>-1.4326647564469914</cla_stall><cda>0</cda><cda_stall>1.4326647564469914</cda_stall><alpha_stall>1.396</alpha_stall><a0>0</a0>
      <area>0.27637</area>
      <upward>-0.7071067811865475 0 -0.7071067811865476</upward>
      <forward>-0.7071067811865476 0 0.7071067811865475</forward>
      <link_name>propeller4</link_name>
      <cp>0 -0.35 0</cp>
    </plugin>

    <plugin name="submarine_propeller_3_4" filename="libLiftDragPlugin.so">
      <air_density>1000</air_density><cla>1.2535816618911175</cla><cla_stall>-1.4326647564469914</cla_stall><cda>0</cda><cda_stall>1.4326647564469914</cda_stall><alpha_stall>1.396</alpha_stall><a0>0</a0>
      <area>0.27637</area>
      <upward>0 0.7071067811865475 -0.7071067811865476</upward>
      <forward>0 -0.7071067811865476 -0.7071067811865475</forward>
      <link_name>propeller4</link_name>
      <cp>-0.35 0 0</cp>
    </plugin>

    <plugin name="submarine_propeller_4_4" filename="libLiftDragPlugin.so">
      <air_density>1000</air_density><cla>1.2535816618911175</cla><cla_stall>-1.4326647564469914</cla_stall><cda>0</cda><cda_stall>1.4326647564469914</cda_stall><alpha_stall>1.396</alpha_stall><a0>0</a0>
      <area>0.27637</area>
      <upward>0.7071067811865476 0 -0.7071067811865475</upward>
      <forward>0.7071067811865475 0 0.7071067811865476</forward>
      <link_name>propeller4</link_name>
      <cp>0 0.35 0</cp>
    </plugin>


    <link name='propeller5'>
      <pose>0.1 0 0.01 0 0 0</pose>
      <inertial>
        <mass>21.820000000000004</mass>
        <inertia>
          <ixx>0.45999415237916674</ixx>
          <ixy>0</ixy>
          <ixz>0</ixz>
          <iyy>0.45999415237916674</iyy>
          <iyz>0</iyz>
          <izz>0.9091666666666668</izz>
        </inertia>
      </inertial>

      
        <visual name=blade1_visual5>
          <pose>0.01716701 0.0 0 0.7853981633974483 0 0.0</pose>
            <geometry>
              <box>
                <size>0.025 0.01 0.0027275</size>
              </box>
            </geometry>
          <material>
            <script>
              <uri>file://media/materials/scripts/gazebo.material</uri>
              <name>Gazebo/Yellow</name>
            </script>
          </material>
        </visual>
        <collision name=blade1_collision5>
          <pose>0.01716701 0.0 0 0.7853981633974483 0 0.0</pose>
            <geometry>
              <box>
                <size>0.025 0.01 0.0027275</size>
              </box>
            </geometry>
        </collision>
        <visual name=blade2_visual5>
          <pose>0.0 0.01716701 0 0.7853981633974483 0 1.5707963267948966</pose>
            <geometry>
              <box>
                <size>0.025 0.01 0.0027275</size>
              </box>
            </geometry>
          <material>
            <script>
              <uri>file://media/materials/scripts/gazebo.material</uri>
              <name>Gazebo/Yellow</name>
            </script>
          </material>
        </visual>
        <collision name=blade2_collision5>
          <pose>0.0 0.01716701 0 0.7853981633974483 0 1.57079632679489606</pose>
            <geometry>
              <box>
                <size>0.025 0.01 0.0027275</size>
              </box>
            </geometry>
        </collision>
      
        <visual name=blade3_visual5>
          <pose>-0.01716701 -0.0 0 -0.7853981633974483 0 0.0</pose>
            <geometry>
              <box>
                <size>0.025 0.01 0.0027275</size>
              </box>
            </geometry>
          <material>
            <script>
              <uri>file://media/materials/scripts/gazebo.material</uri>
              <name>Gazebo/Yellow</name>
            </script>
          </material>
        </visual>
        <collision name=blade3_collision5>
          <pose>-0.01716701 -0.0 0 -0.7853981633974483 0 0.0</pose>
            <geometry>
              <box>
                <size>0.025 0.01 0.0027275</size>
              </box>
            </geometry>
        </collision>
      
        <visual name=blade4_visual5>
          <pose>-0.0 -0.01716701 0 -0.7853981633974483 0 1.5707963267948966</pose>
            <geometry>
              <box>
                <size>0.025 0.01 0.0027275</size>
              </box>
            </geometry>
          <material>
            <script>
              <uri>file://media/materials/scripts/gazebo.material</uri>
              <name>Gazebo/Yellow</name>
            </script>
          </material>
        </visual>
        <collision name=blade4_collision5>
          <pose>-0.0 -0.01716701 0 -0.7853981633974483 0 1.5707963267948966</pose>
            <geometry>
              <box>
                <size>0.025 0.01 0.0027275</size>
              </box>
            </geometry>
        </collision>

    </link>

    <joint name='spinning_joint5' type='revolute'>
      <parent>base_link</parent>
      <child>propeller5</child>
      <axis>
        <xyz>0 0 1</xyz>
        <use_parent_model_frame>1</use_parent_model_frame>
        <limit>
          <lower>-1e+12</lower>
          <upper>1e+12</upper>
          <effort>-1</effort>
          <velocity>-1</velocity>
        </limit>
      </axis>
    </joint>

    <plugin name="submarine_propeller_1_5" filename="libLiftDragPlugin.so">
      <air_density>1000</air_density><cla>1.2535816618911175</cla><cla_stall>-1.4326647564469914</cla_stall><cda>0</cda><cda_stall>1.4326647564469914</cda_stall><alpha_stall>1.396</alpha_stall><a0>0</a0>
      <area>0.27637</area>
      <upward>0 -0.7071067811865476 -0.7071067811865475</upward>
      <forward>0 -0.7071067811865475 0.7071067811865476</forward>
      <link_name>propeller5</link_name>
      <cp>0.35 0 0</cp>
    </plugin>
    <plugin name="submarine_propeller_2_5" filename="libLiftDragPlugin.so">
      <air_density>1000</air_density><cla>1.2535816618911175</cla><cla_stall>-1.4326647564469914</cla_stall><cda>0</cda><cda_stall>1.4326647564469914</cda_stall><alpha_stall>1.396</alpha_stall><a0>0</a0>
      <area>0.27637</area>
      <upward>-0.7071067811865475 0 -0.7071067811865476</upward>
      <forward>-0.7071067811865476 0 0.7071067811865475</forward>
      <link_name>propeller5</link_name>
      <cp>0 -0.35 0</cp>
    </plugin>

    <plugin name="submarine_propeller_3_5" filename="libLiftDragPlugin.so">
      <air_density>1000</air_density><cla>1.2535816618911175</cla><cla_stall>-1.4326647564469914</cla_stall><cda>0</cda><cda_stall>1.4326647564469914</cda_stall><alpha_stall>1.396</alpha_stall><a0>0</a0>
      <area>0.27637</area>
      <upward>0 0.7071067811865475 -0.7071067811865476</upward>
      <forward>0 -0.7071067811865476 -0.7071067811865475</forward>
      <link_name>propeller5</link_name>
      <cp>-0.35 0 0</cp>
    </plugin>

    <plugin name="submarine_propeller_4_5" filename="libLiftDragPlugin.so">
      <air_density>1000</air_density><cla>1.2535816618911175</cla><cla_stall>-1.4326647564469914</cla_stall><cda>0</cda><cda_stall>1.4326647564469914</cda_stall><alpha_stall>1.396</alpha_stall><a0>0</a0>
      <area>0.27637</area>
      <upward>0.7071067811865476 0 -0.7071067811865475</upward>
      <forward>0.7071067811865475 0 0.7071067811865476</forward>
      <link_name>propeller5</link_name>
      <cp>0 0.35 0</cp>
    </plugin>


    <link name='propeller6'>
      <pose>-0.1 0 0.01 0 0 0</pose>
      <inertial>
        <mass>21.820000000000004</mass>
        <inertia>
          <ixx>0.45999415237916674</ixx>
          <ixy>0</ixy>
          <ixz>0</ixz>
          <iyy>0.45999415237916674</iyy>
          <iyz>0</iyz>
          <izz>0.9091666666666668</izz>
        </inertia>
      </inertial>

      
        <visual name=blade1_visual6>
          <pose>0.01716701 0.0 0 0.7853981633974483 0 0.0</pose>
            <geometry>
              <box>
                <size>0.025 0.01 0.0027275</size>
              </box>
            </geometry>
          <material>
            <script>
              <uri>file://media/materials/scripts/gazebo.material</uri>
              <name>Gazebo/Yellow</name>
            </script>
          </material>
        </visual>
        <collision name=blade1_collision6>
          <pose>0.01716701 0.0 0 0.7853981633974483 0 0.0</pose>
            <geometry>
              <box>
                <size>0.025 0.01 0.0027275</size>
              </box>
            </geometry>
        </collision>
        <visual name=blade2_visual6>
          <pose>0.0 0.01716701 0 0.7853981633974483 0 1.5707963267948966</pose>
            <geometry>
              <box>
                <size>0.025 0.01 0.0027275</size>
              </box>
            </geometry>
          <material>
            <script>
              <uri>file://media/materials/scripts/gazebo.material</uri>
              <name>Gazebo/Yellow</name>
            </script>
          </material>
        </visual>
        <collision name=blade2_collision6>
          <pose>0.0 0.01716701 0 0.7853981633974483 0 1.57079632679489606</pose>
            <geometry>
              <box>
                <size>0.025 0.01 0.0027275</size>
              </box>
            </geometry>
        </collision>
      
        <visual name=blade3_visual6>
          <pose>-0.01716701 -0.0 0 -0.7853981633974483 0 0.0</pose>
            <geometry>
              <box>
                <size>0.025 0.01 0.0027275</size>
              </box>
            </geometry>
          <material>
            <script>
              <uri>file://media/materials/scripts/gazebo.material</uri>
              <name>Gazebo/Yellow</name>
            </script>
          </material>
        </visual>
        <collision name=blade3_collision6>
          <pose>-0.01716701 -0.0 0 -0.7853981633974483 0 0.0</pose>
            <geometry>
              <box>
                <size>0.025 0.01 0.0027275</size>
              </box>
            </geometry>
        </collision>
      
        <visual name=blade4_visual6>
          <pose>-0.0 -0.01716701 0 -0.7853981633974483 0 1.5707963267948966</pose>
            <geometry>
              <box>
                <size>0.025 0.01 0.0027275</size>
              </box>
            </geometry>
          <material>
            <script>
              <uri>file://media/materials/scripts/gazebo.material</uri>
              <name>Gazebo/Yellow</name>
            </script>
          </material>
        </visual>
        <collision name=blade4_collision6>
          <pose>-0.0 -0.01716701 0 -0.7853981633974483 0 1.5707963267948966</pose>
            <geometry>
              <box>
                <size>0.025 0.01 0.0027275</size>
              </box>
            </geometry>
        </collision>

    </link>

    <joint name='spinning_joint6' type='revolute'>
      <parent>base_link</parent>
      <child>propeller6</child>
      <axis>
        <xyz>0 0 1</xyz>
        <use_parent_model_frame>1</use_parent_model_frame>
        <limit>
          <lower>-1e+12</lower>
          <upper>1e+12</upper>
          <effort>-1</effort>
          <velocity>-1</velocity>
        </limit>
      </axis>
    </joint>

    <plugin name="submarine_propeller_1_6" filename="libLiftDragPlugin.so">
      <air_density>1000</air_density><cla>1.2535816618911175</cla><cla_stall>-1.4326647564469914</cla_stall><cda>0</cda><cda_stall>1.4326647564469914</cda_stall><alpha_stall>1.396</alpha_stall><a0>0</a0>
      <area>0.27637</area>
      <upward>0 -0.7071067811865476 -0.7071067811865475</upward>
      <forward>0 -0.7071067811865475 0.7071067811865476</forward>
      <link_name>propeller6</link_name>
      <cp>0.35 0 0</cp>
    </plugin>
    <plugin name="submarine_propeller_2_6" filename="libLiftDragPlugin.so">
      <air_density>1000</air_density><cla>1.2535816618911175</cla><cla_stall>-1.4326647564469914</cla_stall><cda>0</cda><cda_stall>1.4326647564469914</cda_stall><alpha_stall>1.396</alpha_stall><a0>0</a0>
      <area>0.27637</area>
      <upward>-0.7071067811865475 0 -0.7071067811865476</upward>
      <forward>-0.7071067811865476 0 0.7071067811865475</forward>
      <link_name>propeller6</link_name>
      <cp>0 -0.35 0</cp>
    </plugin>

    <plugin name="submarine_propeller_3_6" filename="libLiftDragPlugin.so">
      <air_density>1000</air_density><cla>1.2535816618911175</cla><cla_stall>-1.4326647564469914</cla_stall><cda>0</cda><cda_stall>1.4326647564469914</cda_stall><alpha_stall>1.396</alpha_stall><a0>0</a0>
      <area>0.27637</area>
      <upward>0 0.7071067811865475 -0.7071067811865476</upward>
      <forward>0 -0.7071067811865476 -0.7071067811865475</forward>
      <link_name>propeller6</link_name>
      <cp>-0.35 0 0</cp>
    </plugin>

    <plugin name="submarine_propeller_4_6" filename="libLiftDragPlugin.so">
      <air_density>1000</air_density><cla>1.2535816618911175</cla><cla_stall>-1.4326647564469914</cla_stall><cda>0</cda><cda_stall>1.4326647564469914</cda_stall><alpha_stall>1.396</alpha_stall><a0>0</a0>
      <area>0.27637</area>
      <upward>0.7071067811865476 0 -0.7071067811865475</upward>
      <forward>0.7071067811865475 0 0.7071067811865476</forward>
      <link_name>propeller6</link_name>
      <cp>0 0.35 0</cp>
    </plugin>


    <link name='propeller7'>
      <pose>0 0.1 0.01 0 0 0</pose>
      <inertial>
        <mass>21.820000000000004</mass>
        <inertia>
          <ixx>0.45999415237916674</ixx>
          <ixy>0</ixy>
          <ixz>0</ixz>
          <iyy>0.45999415237916674</iyy>
          <iyz>0</iyz>
          <izz>0.9091666666666668</izz>
        </inertia>
      </inertial>

      
        <visual name=blade1_visual7>
          <pose>0.01716701 0.0 0 0.7853981633974483 0 0.0</pose>
            <geometry>
              <box>
                <size>0.025 0.01 0.0027275</size>
              </box>
            </geometry>
          <material>
            <script>
              <uri>file://media/materials/scripts/gazebo.material</uri>
              <name>Gazebo/Yellow</name>
            </script>
          </material>
        </visual>
        <collision name=blade1_collision7>
          <pose>0.01716701 0.0 0 0.7853981633974483 0 0.0</pose>
            <geometry>
              <box>
                <size>0.025 0.01 0.0027275</size>
              </box>
            </geometry>
        </collision>
        <visual name=blade2_visual7>
          <pose>0.0 0.01716701 0 0.7853981633974483 0 1.5707963267948966</pose>
            <geometry>
              <box>
                <size>0.025 0.01 0.0027275</size>
              </box>
            </geometry>
          <material>
            <script>
              <uri>file://media/materials/scripts/gazebo.material</uri>
              <name>Gazebo/Yellow</name>
            </script>
          </material>
        </visual>
        <collision name=blade2_collision7>
          <pose>0.0 0.01716701 0 0.7853981633974483 0 1.57079632679489606</pose>
            <geometry>
              <box>
                <size>0.025 0.01 0.0027275</size>
              </box>
            </geometry>
        </collision>
      
        <visual name=blade3_visual7>
          <pose>-0.01716701 -0.0 0 -0.7853981633974483 0 0.0</pose>
            <geometry>
              <box>
                <size>0.025 0.01 0.0027275</size>
              </box>
            </geometry>
          <material>
            <script>
              <uri>file://media/materials/scripts/gazebo.material</uri>
              <name>Gazebo/Yellow</name>
            </script>
          </material>
        </visual>
        <collision name=blade3_collision7>
          <pose>-0.01716701 -0.0 0 -0.7853981633974483 0 0.0</pose>
            <geometry>
              <box>
                <size>0.025 0.01 0.0027275</size>
              </box>
            </geometry>
        </collision>
      
        <visual name=blade4_visual7>
          <pose>-0.0 -0.01716701 0 -0.7853981633974483 0 1.5707963267948966</pose>
            <geometry>
              <box>
                <size>0.025 0.01 0.0027275</size>
              </box>
            </geometry>
          <material>
            <script>
              <uri>file://media/materials/scripts/gazebo.material</uri>
              <name>Gazebo/Yellow</name>
            </script>
          </material>
        </visual>
        <collision name=blade4_collision7>
          <pose>-0.0 -0.01716701 0 -0.7853981633974483 0 1.5707963267948966</pose>
            <geometry>
              <box>
                <size>0.025 0.01 0.0027275</size>
              </box>
            </geometry>
        </collision>

    </link>

    <joint name='spinning_joint7' type='revolute'>
      <parent>base_link</parent>
      <child>propeller7</child>
      <axis>
        <xyz>0 0 1</xyz>
        <use_parent_model_frame>1</use_parent_model_frame>
        <limit>
          <lower>-1e+12</lower>
          <upper>1e+12</upper>
          <effort>-1</effort>
          <velocity>-1</velocity>
        </limit>
      </axis>
    </joint>

    <plugin name="submarine_propeller_1_7" filename="libLiftDragPlugin.so">
      <air_density>1000</air_density><cla>1.2535816618911175</cla><cla_stall>-1.4326647564469914</cla_stall><cda>0</cda><cda_stall>1.4326647564469914</cda_stall><alpha_stall>1.396</alpha_stall><a0>0</a0>
      <area>0.27637</area>
      <upward>0 -0.7071067811865476 -0.7071067811865475</upward>
      <forward>0 -0.7071067811865475 0.7071067811865476</forward>
      <link_name>propeller7</link_name>
      <cp>0.35 0 0</cp>
    </plugin>
    <plugin name="submarine_propeller_2_7" filename="libLiftDragPlugin.so">
      <air_density>1000</air_density><cla>1.2535816618911175</cla><cla_stall>-1.4326647564469914</cla_stall><cda>0</cda><cda_stall>1.4326647564469914</cda_stall><alpha_stall>1.396</alpha_stall><a0>0</a0>
      <area>0.27637</area>
      <upward>-0.7071067811865475 0 -0.7071067811865476</upward>
      <forward>-0.7071067811865476 0 0.7071067811865475</forward>
      <link_name>propeller7</link_name>
      <cp>0 -0.35 0</cp>
    </plugin>

    <plugin name="submarine_propeller_3_7" filename="libLiftDragPlugin.so">
      <air_density>1000</air_density><cla>1.2535816618911175</cla><cla_stall>-1.4326647564469914</cla_stall><cda>0</cda><cda_stall>1.4326647564469914</cda_stall><alpha_stall>1.396</alpha_stall><a0>0</a0>
      <area>0.27637</area>
      <upward>0 0.7071067811865475 -0.7071067811865476</upward>
      <forward>0 -0.7071067811865476 -0.7071067811865475</forward>
      <link_name>propeller7</link_name>
      <cp>-0.35 0 0</cp>
    </plugin>

    <plugin name="submarine_propeller_4_7" filename="libLiftDragPlugin.so">
      <air_density>1000</air_density><cla>1.2535816618911175</cla><cla_stall>-1.4326647564469914</cla_stall><cda>0</cda><cda_stall>1.4326647564469914</cda_stall><alpha_stall>1.396</alpha_stall><a0>0</a0>
      <area>0.27637</area>
      <upward>0.7071067811865476 0 -0.7071067811865475</upward>
      <forward>0.7071067811865475 0 0.7071067811865476</forward>
      <link_name>propeller7</link_name>
      <cp>0 0.35 0</cp>
    </plugin>


    <link name='propeller8'>
      <pose>0 -0.1 0.01 0 0 0</pose>
      <inertial>
        <mass>21.820000000000004</mass>
        <inertia>
          <ixx>0.45999415237916674</ixx>
          <ixy>0</ixy>
          <ixz>0</ixz>
          <iyy>0.45999415237916674</iyy>
          <iyz>0</iyz>
          <izz>0.9091666666666668</izz>
        </inertia>
      </inertial>

      
        <visual name=blade1_visual8>
          <pose>0.01716701 0.0 0 0.7853981633974483 0 0.0</pose>
            <geometry>
              <box>
                <size>0.025 0.01 0.0027275</size>
              </box>
            </geometry>
          <material>
            <script>
              <uri>file://media/materials/scripts/gazebo.material</uri>
              <name>Gazebo/Yellow</name>
            </script>
          </material>
        </visual>
        <collision name=blade1_collision8>
          <pose>0.01716701 0.0 0 0.7853981633974483 0 0.0</pose>
            <geometry>
              <box>
                <size>0.025 0.01 0.0027275</size>
              </box>
            </geometry>
        </collision>
        <visual name=blade2_visual8>
          <pose>0.0 0.01716701 0 0.7853981633974483 0 1.5707963267948966</pose>
            <geometry>
              <box>
                <size>0.025 0.01 0.0027275</size>
              </box>
            </geometry>
          <material>
            <script>
              <uri>file://media/materials/scripts/gazebo.material</uri>
              <name>Gazebo/Yellow</name>
            </script>
          </material>
        </visual>
        <collision name=blade2_collision8>
          <pose>0.0 0.01716701 0 0.7853981633974483 0 1.57079632679489606</pose>
            <geometry>
              <box>
                <size>0.025 0.01 0.0027275</size>
              </box>
            </geometry>
        </collision>
      
        <visual name=blade3_visual8>
          <pose>-0.01716701 -0.0 0 -0.7853981633974483 0 0.0</pose>
            <geometry>
              <box>
                <size>0.025 0.01 0.0027275</size>
              </box>
            </geometry>
          <material>
            <script>
              <uri>file://media/materials/scripts/gazebo.material</uri>
              <name>Gazebo/Yellow</name>
            </script>
          </material>
        </visual>
        <collision name=blade3_collision8>
          <pose>-0.01716701 -0.0 0 -0.7853981633974483 0 0.0</pose>
            <geometry>
              <box>
                <size>0.025 0.01 0.0027275</size>
              </box>
            </geometry>
        </collision>
      
        <visual name=blade4_visual8>
          <pose>-0.0 -0.01716701 0 -0.7853981633974483 0 1.5707963267948966</pose>
            <geometry>
              <box>
                <size>0.025 0.01 0.0027275</size>
              </box>
            </geometry>
          <material>
            <script>
              <uri>file://media/materials/scripts/gazebo.material</uri>
              <name>Gazebo/Yellow</name>
            </script>
          </material>
        </visual>
        <collision name=blade4_collision8>
          <pose>-0.0 -0.01716701 0 -0.7853981633974483 0 1.5707963267948966</pose>
            <geometry>
              <box>
                <size>0.025 0.01 0.0027275</size>
              </box>
            </geometry>
        </collision>

    </link>

    <joint name='spinning_joint8' type='revolute'>
      <parent>base_link</parent>
      <child>propeller8</child>
      <axis>
        <xyz>0 0 1</xyz>
        <use_parent_model_frame>1</use_parent_model_frame>
        <limit>
          <lower>-1e+12</lower>
          <upper>1e+12</upper>
          <effort>-1</effort>
          <velocity>-1</velocity>
        </limit>
      </axis>
    </joint>

    <plugin name="submarine_propeller_1_8" filename="libLiftDragPlugin.so">
      <air_density>1000</air_density><cla>1.2535816618911175</cla><cla_stall>-1.4326647564469914</cla_stall><cda>0</cda><cda_stall>1.4326647564469914</cda_stall><alpha_stall>1.396</alpha_stall><a0>0</a0>
      <area>0.27637</area>
      <upward>0 -0.7071067811865476 -0.7071067811865475</upward>
      <forward>0 -0.7071067811865475 0.7071067811865476</forward>
      <link_name>propeller8</link_name>
      <cp>0.35 0 0</cp>
    </plugin>
    <plugin name="submarine_propeller_2_8" filename="libLiftDragPlugin.so">
      <air_density>1000</air_density><cla>1.2535816618911175</cla><cla_stall>-1.4326647564469914</cla_stall><cda>0</cda><cda_stall>1.4326647564469914</cda_stall><alpha_stall>1.396</alpha_stall><a0>0</a0>
      <area>0.27637</area>
      <upward>-0.7071067811865475 0 -0.7071067811865476</upward>
      <forward>-0.7071067811865476 0 0.7071067811865475</forward>
      <link_name>propeller8</link_name>
      <cp>0 -0.35 0</cp>
    </plugin>

    <plugin name="submarine_propeller_3_8" filename="libLiftDragPlugin.so">
      <air_density>1000</air_density><cla>1.2535816618911175</cla><cla_stall>-1.4326647564469914</cla_stall><cda>0</cda><cda_stall>1.4326647564469914</cda_stall><alpha_stall>1.396</alpha_stall><a0>0</a0>
      <area>0.27637</area>
      <upward>0 0.7071067811865475 -0.7071067811865476</upward>
      <forward>0 -0.7071067811865476 -0.7071067811865475</forward>
      <link_name>propeller8</link_name>
      <cp>-0.35 0 0</cp>
    </plugin>

    <plugin name="submarine_propeller_4_8" filename="libLiftDragPlugin.so">
      <air_density>1000</air_density><cla>1.2535816618911175</cla><cla_stall>-1.4326647564469914</cla_stall><cda>0</cda><cda_stall>1.4326647564469914</cda_stall><alpha_stall>1.396</alpha_stall><a0>0</a0>
      <area>0.27637</area>
      <upward>0.7071067811865476 0 -0.7071067811865475</upward>
      <forward>0.7071067811865475 0 0.7071067811865476</forward>
      <link_name>propeller8</link_name>
      <cp>0 0.35 0</cp>
    </plugin>


  </model>
  
  
</sdf>
